Workbook

Sheet General
A1: 45931 | B1: Convenio estándar | C1: Convenio estándar | D1: Convenio estándar | E1: Convenio 10% | F1: Convenio 10% | G1: Convenio 10% | H1: Bilateral | I1: Bilateral | J1: Bilateral | K1: AlyCs por RosVal | L1: AlyCs por RosVal | M1: AlyCs por RosVal | N1: Ingresos por liquidaciones | O1: Intereses por desc. cta. cte. | P1: Intereses por desc. cta. cte. | Q1: Intereses por desc. cta. cte. | R1: Intereses por desc. cta. cte. | S1: FCI - ACDI | T1: FCI - ACDI | U1: FCI - ACDI | V1: FCI - ACDI | W1: Total | X1: Total | Y1: Total | Z1: Total | AA1: 3.9550033e+08
A2: Agente | B2: 45870 | C2: 45901 | D2: 45931 | E2: 45870 | F2: 45901 | G2: 45931 | H2: 45870 | I2: 45901 | J2: 45931 | K2: 45870 | L2: 45901 | M2: 45931 | N2: Total | O2: 45870 | P2: 45901 | Q2: 45931 | R2: Total | S2: 45870 | T2: 45901 | U2: 45931 | V2: Total | W2: 45870 | X2: 45901 | Y2: 45931 | Z2: Total | AA2: 1
A3: ARGENTINA | B3: 29690171 | C3: 40873976 | D3: 45909342 | E3: 0 | F3: 0 | G3: 0 | H3: 1251377.9 | I3: 3138081.3 | J3: 3512061.7 | K3: 0 | L3: 0 | M3: 0 | N3: 1.2437501e+08 | O3: 722252.39 | P3: 54159 | Q3: 874386.78 | R3: 1650798.2 | S3: 303840.26 | T3: 419595.24 | U3: 354205.38 | V3: 1077640.9 | W3: 31967642 | X3: 44485812 | Y3: 50649996 | Z3: 1.2710345e+08 | AA3: 0.12806562
A4: BRASIL | B4: 1511691.8 | C4: 1157460.1 | D4: 145000 | E4: 9584609.1 | F4: 14238583 | G4: 11021643 | H4: 5302808 | I4: 4135007 | J4: 14323207 | K4: 0 | L4: 0 | M4: 0 | N4: 61420010 | O4: 26092 | P4: 244373.86 | Q4: 852521.78 | R4: 1122987.6 | S4: 718839.22 | T4: 772404.08 | U4: 972682.96 | V4: 2463926.3 | W4: 17144040 | X4: 20547829 | Y4: 27315055 | Z4: 65006924 | AA4: 0.069064557
A5: PALMEIRAS | B5: 12718.01 | C5: 106180.66 | D5: 19430.87 | E5: 4129470 | F5: 6856389.5 | G5: 6616919.7 | H5: 3131514.7 | I5: 4272015 | J5: 5681626.9 | K5: 0 | L5: 0 | M5: 0 | N5: 30826265 | O5: 1027170.5 | P5: 197919.06 | Q5: 558901.72 | R5: 1783991.3 | S5: 1569504.6 | T5: 1737256.1 | U5: 1296399.3 | V5: 4603160.1 | W5: 9870377.9 | X5: 13169760 | Y5: 14173279 | Z5: 37213417 | AA5: 0.035836325
A6: FLAMENGO | B6: 449928.14 | C6: 10594632 | D6: 2432106.2 | E6: 6487611.9 | F6: 4569000 | G6: 5054678.8 | H6: 614644.44 | I6: 1564432.3 | J6: 1322434.2 | K6: 0 | L6: 0 | M6: 0 | N6: 33089468 | O6: 1373360.4 | P6: 80303.26 | Q6: -893959.74 | R6: 559703.95 | S6: 331360.67 | T6: 381534.46 | U6: 195127.25 | V6: 908022.37 | W6: 9256905.6 | X6: 17189902 | Y6: 8110386.7 | Z6: 34557195 | AA6: 0.02050665
A7: LIMA | B7: 3191920.3 | C7: 7586840.3 | D7: 6745349.1 | E7: 0 | F7: 0 | G7: 0 | H7: 0 | I7: 0 | J7: 0 | K7: 0 | L7: 0 | M7: 0 | N7: 17524110 | O7: 0 | P7: 42202.7 | Q7: 117711.71 | R7: 159914.41 | S7: 13507.661 | T7: 12319.486 | U7: 11650.853 | V7: 37477.999 | W7: 3205428 | X7: 7641362.5 | Y7: 6874711.7 | Z7: 17721502 | AA7: 0.017382316
A8: PERU | B8: 248014.75 | C8: 767595 | D8: 467545.5 | E8: 4854838.2 | F8: 5698298.8 | G8: 6807435.6 | H8: 5979888.1 | I8: 428642.05 | J8: 3620824.9 | K8: 0 | L8: 0 | M8: 0 | N8: 28873083 | O8: 39150.8 | P8: 13582.7 | Q8: 28209.4 | R8: 80942.9 | S8: 61146.563 | T8: 66127.113 | U8: 60451.608 | V8: 187725.28 | W8: 11183038 | X8: 6974245.7 | Y8: 10984467 | Z8: 29141751 | AA8: 0.027773598
A9: VITOR ROQUE | B9: 0 | C9: 288250 | D9: 8843100.5 | E9: 4495063.6 | F9: 6807138.2 | G9: 11704385 | H9: 317572.13 | I9: 1364413.3 | J9: 1767233.4 | K9: 0 | L9: 0 | M9: 0 | N9: 35587156 | O9: 64724.85 | P9: 2088182.4 | Q9: -904332.21 | R9: 1248575.1 | S9: 487685.41 | T9: 848242.12 | U9: 1092852.1 | V9: 2428779.6 | W9: 5365046 | X9: 11396226 | Y9: 22503239 | Z9: 39264511 | AA9: 0.056898155
A10: MENGAO | B10: 32299.6 | C10: 4142367.9 | D10: 190886 | E10: 4129470 | F10: 4569000 | G10: 4486740 | H10: 49469.212 | I10: 28007.874 | J10: 59365.157 | K10: 0 | L10: 0 | M10: 0 | N10: 17687606 | O10: 52353.6 | P10: 122692.52 | Q10: 58547.5 | R10: 233593.62 | S10: 44070.02 | T10: 45361.441 | U10: 19290.365 | V10: 108721.83 | W10: 4307662.4 | X10: 8907429.8 | Y10: 4814829 | Z10: 18029921 | AA10: 0.01217402
A11: PAULISTA | B11: 0 | C11: 0 | D11: 0 | E11: 4129470 | F11: 4569000 | G11: 4486740 | H11: 0 | I11: 0 | J11: 0 | K11: 0 | L11: 0 | M11: 0 | N11: 13185210 | O11: 0 | P11: 0 | Q11: 0 | R11: 0 | S11: 5484.4902 | T11: 0 | U11: 96464.615 | V11: 101949.1 | W11: 4134954.5 | X11: 4569000 | Y11: 4583204.6 | Z11: 13287159 | AA11: 0.011588371
A12: CARIOCAS | B12: 69585.49 | C12: 0 | D12: 0 | E12: 4795720.1 | F12: 4569000 | G12: 5990285 | H12: 0 | I12: 2104.725 | J12: 50227.747 | K12: 0 | L12: 0 | M12: 0 | N12: 15476923 | O12: 0 | P12: 14349.2 | Q12: 0 | R12: 14349.2 | S12: 4115.7743 | T12: 69503.755 | U12: 8039.2684 | V12: 81658.797 | W12: 4869421.4 | X12: 4654957.7 | Y12: 6048552 | Z12: 15572931 | AA12: 0.015293418
A13: BRUNO ENRIQUE | B13: 1845075.3 | C13: 3091058.2 | D13: 2770489.4 | E13: 0 | F13: 0 | G13: 0 | H13: 554.3676 | I13: 0 | J13: 289980.73 | K13: 0 | L13: 0 | M13: 0 | N13: 7997158 | O13: 0 | P13: 79493.78 | Q13: 14988.1 | R13: 94481.88 | S13: 0 | T13: 0 | U13: 0 | V13: 0 | W13: 1845629.7 | X13: 3170552 | Y13: 3075458.2 | Z13: 8091639.9 | AA13: 0.0077761206
A14: FLACO LOPEZ | B14: 3145507.3 | C14: 2756630.8 | D14: 4374130.7 | E14: 0 | F14: 0 | G14: 0 | H14: 0 | I14: 0 | J14: 0 | K14: 0 | L14: 0 | M14: 0 | N14: 10276269 | O14: 0 | P14: 12970.2 | Q14: 78687.55 | R14: 91657.75 | S14: 0 | T14: 214.82578 | U14: 0 | V14: 214.82578 | W14: 3145507.3 | X14: 2769815.8 | Y14: 4452818.3 | Z14: 10368141 | AA14: 0.011258697
... A38: GALLARDO | B38: 6446872.8 | C38: 8069276.7 | D38: 14426638 | E38: 0 | F38: 0 | G38: 0 | H38: 0 | I38: 0 | J38: 0 | K38: 0 | L38: 0 | M38: 0 | N38: 28942788 | O38: 0 | P38: 0 | Q38: 0 | R38: 0 | S38: 8444.0294 | T38: 6445.3422 | U38: 3097.7952 | V38: 17987.167 | W38: 6455316.9 | X38: 8075722.1 | Y38: 14429736 | Z38: 28960775 | AA38: 0.036484764
A39: CRESPO | B39: 0 | C39: 64424.15 | D39: 116744.2 | E39: 0 | F39: 0 | G39: 0 | H39: 0 | I39: 0 | J39: 0 | K39: 0 | L39: 0 | M39: 0 | N39: 181168.35 | O39: 0 | P39: 0 | Q39: 0 | R39: 0 | S39: 0 | T39: 0 | U39: 0 | V39: 0 | W39: 0 | X39: 64424.15 | Y39: 116744.2 | Z39: 181168.35
A40: RONALDINHO | B40: 178581.27 | C40: 166769.35 | D40: 206841.19 | E40: 0 | F40: 0 | G40: 0 | H40: 0 | I40: 0 | J40: 0 | K40: 0 | L40: 0 | M40: 0 | N40: 552191.81 | O40: 0 | P40: 0 | Q40: 0 | R40: 0 | S40: 0 | T40: 0 | U40: 0 | V40: 0 | W40: 178581.27 | X40: 166769.35 | Y40: 206841.19 | Z40: 552191.81 | AA40: 0.00052298614
A41: NEYMAR | B41: 119902.34 | C41: 76713.44 | D41: 105384.58 | E41: 0 | F41: 0 | G41: 0 | H41: 0 | I41: 0 | J41: 0 | K41: 0 | L41: 0 | M41: 0 | N41: 302000.36 | O41: 0 | P41: 0 | Q41: 0 | R41: 0 | S41: 705.15194 | T41: 221.412 | U41: 65 | V41: 991.56394 | W41: 120607.49 | X41: 76934.852 | Y41: 105449.58 | Z41: 302991.92 | AA41: 0.00026662324
A42: LEONEL MESSI | B42: 0 | C42: 0 | D42: 0 | E42: 6733406.2 | F42: 18271700 | G42: 10892998 | H42: 0 | I42: 0 | J42: 0 | K42: 0 | L42: 0 | M42: 0 | N42: 35898104 | O42: 0 | P42: 47761.64 | Q42: 0 | R42: 47761.64 | S42: 80515.113 | T42: 85673.044 | U42: 95852.971 | V42: 262041.13 | W42: 6813921.3 | X42: 18405135 | Y42: 10988850 | Z42: 36207907 | AA42: 0.027784681
A43: CRISTIANO RONALDO | B43: 0 | C43: 0 | D43: 157681.36 | E43: 0 | F43: 0 | G43: 0 | H43: 0 | I43: 0 | J43: 0 | K43: 0 | L43: 0 | M43: 0 | N43: 157681.36 | O43: 0 | P43: 0 | Q43: 0 | R43: 0 | S43: 0 | T43: 0 | U43: 0 | V43: 0 | W43: 0 | X43: 0 | Y43: 157681.36 | Z43: 157681.36 | AA43: 0.00039868832
A44: RODRIGO DE PAUL | B44: 260735.65 | C44: 7628.7 | D44: 49797.06 | E44: 0 | F44: 0 | G44: 0 | H44: 0 | I44: 0 | J44: 0 | K44: 0 | L44: 0 | M44: 0 | N44: 318161.41 | O44: 0 | P44: 0 | Q44: 0 | R44: 0 | S44: 0 | T44: 0 | U44: 0 | V44: 0 | W44: 260735.65 | X44: 7628.7 | Y44: 49797.06 | Z44: 318161.41 | AA44: 0.00012590902
A45: CHIQUI TAPIA | B45: 12416387 | C45: 13828954 | D45: 21356194 | E45: 0 | F45: 0 | G45: 0 | H45: 973117.71 | I45: 1704199.3 | J45: 7753472.6 | K45: 0 | L45: 0 | M45: 0 | N45: 58032324 | O45: 26277.5 | P45: 28796.1 | Q45: 318453.32 | R45: 373526.92 | S45: 2128.0324 | T45: 4776.2933 | U45: 11811.667 | V45: 18715.993 | W45: 13417910 | X45: 15566726 | Y45: 29439931 | Z45: 58424567 | AA45: 0.074437185
A46: DIBU MARTINEZ | B46: 2689018 | C46: 2195794.3 | D46: 5154994.8 | E46: 0 | F46: 0 | G46: 0 | H46: 198637.33 | I46: 59052.616 | J46: 59126.115 | K46: 0 | L46: 0 | M46: 0 | N46: 10356623 | O46: 0 | P46: 27890.1 | Q46: 33977.04 | R46: 61867.14 | S46: 0 | T46: 0 | U46: 0 | V46: 0 | W46: 2887655.3 | X46: 2282737 | Y46: 5248097.9 | Z46: 10418490 | AA46: 0.013269516
A47: CUTI ROMERO | B47: 32316.9 | C47: 188125.66 | D47: 309589.03 | E47: 0 | F47: 0 | G47: 0 | H47: 0 | I47: 0 | J47: 0 | K47: 0 | L47: 0 | M47: 0 | N47: 530031.59 | O47: 0 | P47: 0 | Q47: 0 | R47: 0 | S47: 0 | T47: 0 | U47: 0 | V47: 0 | W47: 32316.9 | X47: 188125.66 | Y47: 309589.03 | Z47: 530031.59 | AA47: 0.00078277819
A48: PEPI ZAPATA | B48: 202808.12 | C48: 229671.42 | D48: 214769.21 | E48: 0 | F48: 0 | G48: 0 | H48: 0 | I48: 0 | J48: 0 | K48: 0 | L48: 0 | M48: 0 | N48: 647248.75 | O48: 0 | P48: 0 | Q48: 0 | R48: 0 | S48: 0 | T48: 0 | U48: 0 | V48: 0 | W48: 202808.12 | X48: 229671.42 | Y48: 214769.21 | Z48: 647248.75 | AA48: 0.00054303168
A49: TANO VELA | B49: 396870.67 | C49: 426783.8 | D49: 252035.15 | E49: 0 | F49: 0 | G49: 0 | H49: 0 | I49: 0 | J49: 0 | K49: 0 | L49: 0 | M49: 0 | N49: 1075689.6 | O49: 0 | P49: 0 | Q49: 0 | R49: 0 | S49: 0 | T49: 0 | U49: 0 | V49: 0 | W49: 396870.67 | X49: 426783.8 | Y49: 252035.15 | Z49: 1075689.6 | AA49: 0.00063725649
A50: JULIAN MAIDANA | B50: 4581299.8 | C50: 5643192.1 | D50: 6471053.6 | E50: 0 | F50: 0 | G50: 0 | H50: 0 | I50: 0 | J50: 0 | K50: 0 | L50: 0 | M50: 0 | N50: 16695546 | O50: 0 | P50: 40888 | Q50: 64911.22 | R50: 105799.22 | S50: 0 | T50: 0 | U50: 0 | V50: 0 | W50: 4581299.8 | X50: 5684080.1 | Y50: 6535964.8 | Z50: 16801345 | AA50: 0.016525814
A51: FERNANDO BELLUSCHI | B51: 0 | C51: 0 | D51: 10738.75 | E51: 0 | F51: 0 | G51: 0 | H51: 0 | I51: 0 | J51: 0 | K51: 0 | L51: 0 | M51: 0 | N51: 10738.75 | O51: 0 | P51: 0 | Q51: 0 | R51: 0 | S51: 0 | T51: 0 | U51: 0 | V51: 0 | W51: 0 | X51: 0 | Y51: 10738.75 | Z51: 10738.75 | AA51: 2.7152316e-05
... A79: SHEVSHENKO | B79: 0 | C79: 0 | D79: 0 | E79: 0 | F79: 0 | G79: 0 | H79: 0 | I79: 0 | J79: 0 | K79: 0 | L79: 0 | M79: 0 | N79: 0 | O79: 0 | P79: 0 | Q79: 0 | R79: 0 | S79: 0 | T79: 0 | U79: 0 | V79: 0 | W79: 0 | X79: 0 | Y79: 0 | Z79: 0 | AA79: 0
A81: Total | B81: =SUM(B3:B79) -> 1.2620912e+08 | C81: =SUM(C3:C79) -> 1.989234e+08 | D81: =SUM(D3:D79) -> 2.2214534e+08 | E81: =SUM(E3:E79) -> 82059844 | F81: =SUM(F3:F79) -> 1.2161886e+08 | G81: =SUM(G3:G79) -> 1.0715617e+08 | H81: =SUM(H3:H79) -> 23798216 | I81: =SUM(I3:I79) -> 45340087 | ... Z81: =SUM(Z3:Z79) -> 1.0179902e+09
A82: Sheet | B82: =+'[1]Convenio Estándar'!AS101 -> 1.2620912e+08 | C82: =+'[1]Convenio Estándar'!AT101 -> 1.989234e+08 | D82: =+'[1]Convenio Estándar'!AU101 -> 2.2214534e+08 | E82: =+'[1]Convenio 10%'!AS20 -> 82059844 | F82: =+'[1]Convenio 10%'!AT20 -> 1.2161886e+08 | G82: =+'[1]Convenio 10%'!AU20 -> 1.0715617e+08 | H82: =+[1]Bilateral!AT49 -> -0.58217371 | I82: =+[1]Bilateral!AU49 -> 0.90518853 | J82: =+[1]Bilateral!AV49 -> 0.30974069 | K82: 0 | L82: 0 | M82: 0 | O82: =+'[1]Intereses por desc. cta. cte.'!AS81 -> 4618809.7 | P82: =+'[1]Intereses por desc. cta. cte.'!AT81 -> 10462372 | Q82: =+'[1]Intereses por desc. cta. cte.'!AU81 -> 1753215.2 | S82: =+'[1]FCI - ACDI'!AS120 -> 4248660.2 | T82: =+'[1]FCI - ACDI'!AT120 -> 5210523.2 | U82: =+'[1]FCI - ACDI'!AU120 -> 5061842.5 | Y82: =+'[1]Por Agente - Anual'!CJ96 -> 3.9550033e+08
B83: =+B81-B82 -> 0 | C83: =+C81-C82 -> 0 | D83: =+D81-D82 -> 0 | E83: =+E81-E82 -> 0 | F83: =+F81-F82 -> 0 | G83: =+G81-G82 -> 0 | H83: =+H81-H82 -> 23798216 | I83: =+I81-I82 -> 45340086 | ... M83: =+M81-M82 -> 0 | N83: 0 | O83: =+O81-O82 -> 0 | P83: =+P81-P82 -> 0 | Q83: =+Q81-Q82 -> 0 | R83: 0 | S83: =+S81-S82 -> 0 | T83: =+T81-T82 -> 0 | U83: =+U81-U82 -> 0 | V83: =+SUM(B83:U83) -> 1.2852206e+08 | Y83: =+Y82-Y81 -> 0
V84: Control | Y84: Control

Sheet Estandar
A1: Agente | B1: =+General!B2 -> 45870 | C1: =+General!C2 -> 45901 | D1: =+General!D2 -> 45931
A2: =+General!A3 -> ARGENTINA | B2: =+IFERROR(VLOOKUP(A2,General!$A$3:$D$79,2,FALSE),0) -> 29690171 | C2: =IFERROR(VLOOKUP(A2,General!$A$3:$C$79,3,FALSE),0) -> 40873976 | D2: =IFERROR(VLOOKUP(A2,General!$A$3:$D$79,4,FALSE),0) -> 45909342
A3: =+General!A4 -> BRASIL | B3: =+IFERROR(VLOOKUP(A3,General!$A$3:$D$79,2,FALSE),0) -> 1511691.8 | C3: =IFERROR(VLOOKUP(A3,General!$A$3:$C$79,3,FALSE),0) -> 1157460.1 | D3: =IFERROR(VLOOKUP(A3,General!$A$3:$D$79,4,FALSE),0) -> 145000
A4: =+General!A5 -> PALMEIRAS | B4: =+IFERROR(VLOOKUP(A4,General!$A$3:$D$79,2,FALSE),0) -> 12718.01 | C4: =IFERROR(VLOOKUP(A4,General!$A$3:$C$79,3,FALSE),0) -> 106180.66 | D4: =IFERROR(VLOOKUP(A4,General!$A$3:$D$79,4,FALSE),0) -> 19430.87
A5: =+General!A6 -> FLAMENGO | B5: =+IFERROR(VLOOKUP(A5,General!$A$3:$D$79,2,FALSE),0) -> 449928.14 | C5: =IFERROR(VLOOKUP(A5,General!$A$3:$C$79,3,FALSE),0) -> 10594632 | D5: =IFERROR(VLOOKUP(A5,General!$A$3:$D$79,4,FALSE),0) -> 2432106.2
A6: =+General!A7 -> LIMA | B6: =+IFERROR(VLOOKUP(A6,General!$A$3:$D$79,2,FALSE),0) -> 3191920.3 | C6: =IFERROR(VLOOKUP(A6,General!$A$3:$C$79,3,FALSE),0) -> 7586840.3 | D6: =IFERROR(VLOOKUP(A6,General!$A$3:$D$79,4,FALSE),0) -> 6745349.1
A7: =+General!A8 -> PERU | B7: =+IFERROR(VLOOKUP(A7,General!$A$3:$D$79,2,FALSE),0) -> 248014.75 | C7: =IFERROR(VLOOKUP(A7,General!$A$3:$C$79,3,FALSE),0) -> 767595 | D7: =IFERROR(VLOOKUP(A7,General!$A$3:$D$79,4,FALSE),0) -> 467545.5
A8: =+General!A9 -> VITOR ROQUE | B8: =+IFERROR(VLOOKUP(A8,General!$A$3:$D$79,2,FALSE),0) -> 0 | C8: =IFERROR(VLOOKUP(A8,General!$A$3:$C$79,3,FALSE),0) -> 288250 | D8: =IFERROR(VLOOKUP(A8,General!$A$3:$D$79,4,FALSE),0) -> 8843100.5
A9: =+General!A10 -> MENGAO | B9: =+IFERROR(VLOOKUP(A9,General!$A$3:$D$79,2,FALSE),0) -> 32299.6 | C9: =IFERROR(VLOOKUP(A9,General!$A$3:$C$79,3,FALSE),0) -> 4142367.9 | D9: =IFERROR(VLOOKUP(A9,General!$A$3:$D$79,4,FALSE),0) -> 190886
A10: =+General!A11 -> PAULISTA | B10: =+IFERROR(VLOOKUP(A10,General!$A$3:$D$79,2,FALSE),0) -> 0 | C10: =IFERROR(VLOOKUP(A10,General!$A$3:$C$79,3,FALSE),0) -> 0 | D10: =IFERROR(VLOOKUP(A10,General!$A$3:$D$79,4,FALSE),0) -> 0
A11: =+General!A12 -> CARIOCAS | B11: =+IFERROR(VLOOKUP(A11,General!$A$3:$D$79,2,FALSE),0) -> 69585.49 | C11: =IFERROR(VLOOKUP(A11,General!$A$3:$C$79,3,FALSE),0) -> 0 | D11: =IFERROR(VLOOKUP(A11,General!$A$3:$D$79,4,FALSE),0) -> 0
A12: =+General!A13 -> BRUNO ENRIQUE | B12: =+IFERROR(VLOOKUP(A12,General!$A$3:$D$79,2,FALSE),0) -> 1845075.3 | C12: =IFERROR(VLOOKUP(A12,General!$A$3:$C$79,3,FALSE),0) -> 3091058.2 | D12: =IFERROR(VLOOKUP(A12,General!$A$3:$D$79,4,FALSE),0) -> 2770489.4
A13: =+General!A14 -> FLACO LOPEZ | B13: =+IFERROR(VLOOKUP(A13,General!$A$3:$D$79,2,FALSE),0) -> 3145507.3 | C13: =IFERROR(VLOOKUP(A13,General!$A$3:$C$79,3,FALSE),0) -> 2756630.8 | D13: =IFERROR(VLOOKUP(A13,General!$A$3:$D$79,4,FALSE),0) -> 4374130.7
... A50: =+General!A51 -> FERNANDO BELLUSCHI | B50: =+IFERROR(VLOOKUP(A50,General!$A$3:$D$79,2,FALSE),0) -> 0 | C50: =IFERROR(VLOOKUP(A50,General!$A$3:$C$79,3,FALSE),0) -> 0 | D50: =IFERROR(VLOOKUP(A50,General!$A$3:$D$79,4,FALSE),0) -> 10738.75
A51: =+General!A53 -> RUBEN CAPRIA | B51: =+IFERROR(VLOOKUP(A51,General!$A$3:$D$79,2,FALSE),0) -> 21335.45 | C51: =IFERROR(VLOOKUP(A51,General!$A$3:$C$79,3,FALSE),0) -> 33920.53 | D51: =IFERROR(VLOOKUP(A51,General!$A$3:$D$79,4,FALSE),0) -> 21716.57
A52: =+General!A52 -> BOMBON ROSADA | B52: =+IFERROR(VLOOKUP(A52,General!$A$3:$D$79,2,FALSE),0) -> 0 | C52: =IFERROR(VLOOKUP(A52,General!$A$3:$C$79,3,FALSE),0) -> 3.88 | D52: =IFERROR(VLOOKUP(A52,General!$A$3:$D$79,4,FALSE),0) -> 0
A53: =+General!A54 -> IGNACIO SCOCCO | B53: =+IFERROR(VLOOKUP(A53,General!$A$3:$D$79,2,FALSE),0) -> 6708659.2 | C53: =IFERROR(VLOOKUP(A53,General!$A$3:$C$79,3,FALSE),0) -> 9915559.9 | D53: =IFERROR(VLOOKUP(A53,General!$A$3:$D$79,4,FALSE),0) -> 13134889
A54: =+General!A55 -> MEMO BORGUELO | B54: =+IFERROR(VLOOKUP(A54,General!$A$3:$D$79,2,FALSE),0) -> 7914.2 | C54: =IFERROR(VLOOKUP(A54,General!$A$3:$C$79,3,FALSE),0) -> 0 | D54: =IFERROR(VLOOKUP(A54,General!$A$3:$D$79,4,FALSE),0) -> 0
A55: =+General!A56 -> JUSTO VILLAR | B55: =+IFERROR(VLOOKUP(A55,General!$A$3:$D$79,2,FALSE),0) -> 12414969 | C55: =IFERROR(VLOOKUP(A55,General!$A$3:$C$79,3,FALSE),0) -> 14809298 | D55: =IFERROR(VLOOKUP(A55,General!$A$3:$D$79,4,FALSE),0) -> 18185870
A56: =+General!A57 -> GERMAN RE | B56: =+IFERROR(VLOOKUP(A56,General!$A$3:$D$79,2,FALSE),0) -> 0 | C56: =IFERROR(VLOOKUP(A56,General!$A$3:$C$79,3,FALSE),0) -> 0 | D56: =IFERROR(VLOOKUP(A56,General!$A$3:$D$79,4,FALSE),0) -> 0
A57: =+General!A58 -> GUILLERMO MARINO | B57: =+IFERROR(VLOOKUP(A57,General!$A$3:$D$79,2,FALSE),0) -> 83153 | C57: =IFERROR(VLOOKUP(A57,General!$A$3:$C$79,3,FALSE),0) -> 360903.5 | D57: =IFERROR(VLOOKUP(A57,General!$A$3:$D$79,4,FALSE),0) -> 1490934.5
A58: =+General!A59 -> SANTIAGO SALCEDO | B58: =+IFERROR(VLOOKUP(A58,General!$A$3:$D$79,2,FALSE),0) -> 0 | C58: =IFERROR(VLOOKUP(A58,General!$A$3:$C$79,3,FALSE),0) -> 0 | D58: =IFERROR(VLOOKUP(A58,General!$A$3:$D$79,4,FALSE),0) -> 0
A59: =+General!A60 -> TACUARA CARDOZO | B59: =+IFERROR(VLOOKUP(A59,General!$A$3:$D$79,2,FALSE),0) -> 7763192.8 | C59: =IFERROR(VLOOKUP(A59,General!$A$3:$C$79,3,FALSE),0) -> 9296752.5 | D59: =IFERROR(VLOOKUP(A59,General!$A$3:$D$79,4,FALSE),0) -> 6224243.9
A60: =+General!A61 -> ESCOPETA BOGHOSSIAN | B60: =+IFERROR(VLOOKUP(A60,General!$A$3:$D$79,2,FALSE),0) -> 1227216.3 | C60: =IFERROR(VLOOKUP(A60,General!$A$3:$C$79,3,FALSE),0) -> 3590994.1 | D60: =IFERROR(VLOOKUP(A60,General!$A$3:$D$79,4,FALSE),0) -> 4032713
A61: =+General!A62 -> DAMIAN MANSO | B61: =+IFERROR(VLOOKUP(A61,General!$A$3:$D$79,2,FALSE),0) -> 190897.89 | C61: =IFERROR(VLOOKUP(A61,General!$A$3:$C$79,3,FALSE),0) -> 0 | D61: =IFERROR(VLOOKUP(A61,General!$A$3:$D$79,4,FALSE),0) -> 0
A62: =+General!A63 -> MAURO ROSALES | B62: =+IFERROR(VLOOKUP(A62,General!$A$3:$D$79,2,FALSE),0) -> 376371.34 | C62: =IFERROR(VLOOKUP(A62,General!$A$3:$C$79,3,FALSE),0) -> 1055669.4 | D62: =IFERROR(VLOOKUP(A62,General!$A$3:$D$79,4,FALSE),0) -> 462279.17
A63: =+General!A64 -> TURCO HUSAIN | B63: =+IFERROR(VLOOKUP(A63,General!$A$3:$D$79,2,FALSE),0) -> 0 | C63: =IFERROR(VLOOKUP(A63,General!$A$3:$C$79,3,FALSE),0) -> 0 | D63: =IFERROR(VLOOKUP(A63,General!$A$3:$D$79,4,FALSE),0) -> 0
A64: =+General!A65 -> LUCAS BERNARDI | B64: =+IFERROR(VLOOKUP(A64,General!$A$3:$D$79,2,FALSE),0) -> 241979.18 | C64: =IFERROR(VLOOKUP(A64,General!$A$3:$C$79,3,FALSE),0) -> 85234.51 | D64: =IFERROR(VLOOKUP(A64,General!$A$3:$D$79,4,FALSE),0) -> 105616.05
... A78: =+General!A79 -> SHEVSHENKO | B78: =+IFERROR(VLOOKUP(A78,General!$A$3:$D$79,2,FALSE),0) -> 0 | C78: =IFERROR(VLOOKUP(A78,General!$A$3:$C$79,3,FALSE),0) -> 0 | D78: =IFERROR(VLOOKUP(A78,General!$A$3:$D$79,4,FALSE),0) -> 0
A82: Total
A83: Sheet

Sheet Convenio 10%
A1: Agente | B1: =+General!E2 -> 45870 | C1: =+General!F2 -> 45901 | D1: =+General!G2 -> 45931
A2: =+General!A3 -> ARGENTINA | B2: =+General!E3 -> 0 | C2: =+General!F3 -> 0 | D2: =+General!G3 -> 0
A3: =+General!A4 -> BRASIL | B3: =+General!E4 -> 9584609.1 | C3: =+General!F4 -> 14238583 | D3: =+General!G4 -> 11021643
A4: =+General!A5 -> PALMEIRAS | B4: =+General!E5 -> 4129470 | C4: =+General!F5 -> 6856389.5 | D4: =+General!G5 -> 6616919.7
A5: =+General!A6 -> FLAMENGO | B5: =+General!E6 -> 6487611.9 | C5: =+General!F6 -> 4569000 | D5: =+General!G6 -> 5054678.8
A6: =+General!A7 -> LIMA | B6: =+General!E7 -> 0 | C6: =+General!F7 -> 0 | D6: =+General!G7 -> 0
A7: =+General!A8 -> PERU | B7: =+General!E8 -> 4854838.2 | C7: =+General!F8 -> 5698298.8 | D7: =+General!G8 -> 6807435.6
A8: =+General!A9 -> VITOR ROQUE | B8: =+General!E9 -> 4495063.6 | C8: =+General!F9 -> 6807138.2 | D8: =+General!G9 -> 11704385
A9: =+General!A10 -> MENGAO | B9: =+General!E10 -> 4129470 | C9: =+General!F10 -> 4569000 | D9: =+General!G10 -> 4486740
A10: =+General!A11 -> PAULISTA | B10: =+General!E11 -> 4129470 | C10: =+General!F11 -> 4569000 | D10: =+General!G11 -> 4486740
A11: =+General!A12 -> CARIOCAS | B11: =+General!E12 -> 4795720.1 | C11: =+General!F12 -> 4569000 | D11: =+General!G12 -> 5990285
A12: =+General!A13 -> BRUNO ENRIQUE | B12: =+General!E13 -> 0 | C12: =+General!F13 -> 0 | D12: =+General!G13 -> 0
A13: =+General!A14 -> FLACO LOPEZ | B13: =+General!E14 -> 0 | C13: =+General!F14 -> 0 | D13: =+General!G14 -> 0
... A77: =+General!A78 -> KUOLO MUANI | B77: =+General!E78 -> 0 | C77: =+General!F78 -> 0 | D77: =+General!G78 -> 0
A80: Total
A81: Sheet

Sheet Bilateral
A1: Agente | B1: =+General!H2 -> 45870 | C1: =+General!I2 -> 45901 | D1: =+General!J2 -> 45931
A2: =+General!A3 -> ARGENTINA | B2: =+General!H3 -> 1251377.9 | C2: =+General!I3 -> 3138081.3 | D2: =+General!J3 -> 3512061.7
A3: =+General!A4 -> BRASIL | B3: =+General!H4 -> 5302808 | C3: =+General!I4 -> 4135007 | D3: =+General!J4 -> 14323207
A4: =+General!A5 -> PALMEIRAS | B4: =+General!H5 -> 3131514.7 | C4: =+General!I5 -> 4272015 | D4: =+General!J5 -> 5681626.9
A5: =+General!A6 -> FLAMENGO | B5: =+General!H6 -> 614644.44 | C5: =+General!I6 -> 1564432.3 | D5: =+General!J6 -> 1322434.2
A6: =+General!A7 -> LIMA | B6: =+General!H7 -> 0 | C6: =+General!I7 -> 0 | D6: =+General!J7 -> 0
A7: =+General!A8 -> PERU | B7: =+General!H8 -> 5979888.1 | C7: =+General!I8 -> 428642.05 | D7: =+General!J8 -> 3620824.9
A8: =+General!A9 -> VITOR ROQUE | B8: =+General!H9 -> 317572.13 | C8: =+General!I9 -> 1364413.3 | D8: =+General!J9 -> 1767233.4
A9: =+General!A10 -> MENGAO | B9: =+General!H10 -> 49469.212 | C9: =+General!I10 -> 28007.874 | D9: =+General!J10 -> 59365.157
A10: =+General!A11 -> PAULISTA | B10: =+General!H11 -> 0 | C10: =+General!I11 -> 0 | D10: =+General!J11 -> 0
A11: =+General!A12 -> CARIOCAS | B11: =+General!H12 -> 0 | C11: =+General!I12 -> 2104.725 | D11: =+General!J12 -> 50227.747
A12: =+General!A13 -> BRUNO ENRIQUE | B12: =+General!H13 -> 554.3676 | C12: =+General!I13 -> 0 | D12: =+General!J13 -> 289980.73
A13: =+General!A14 -> FLACO LOPEZ | B13: =+General!H14 -> 0 | C13: =+General!I14 -> 0 | D13: =+General!J14 -> 0
... A77: =+General!A78 -> KUOLO MUANI | B77: =+General!H78 -> 0 | C77: =+General!I78 -> 0 | D77: =+General!J78 -> 0
A79: Total
A80: Sheet

Sheet AlyC
A1: Agente | B1: =+General!K2 -> 45870 | C1: =+General!L2 -> 45901 | D1: =+General!M2 -> 45931
A2: =+General!A3 -> ARGENTINA | B2: =+General!K3 -> 0 | C2: =+General!L3 -> 0 | D2: =+General!M3 -> 0
A3: =+General!A4 -> BRASIL | B3: =+General!K4 -> 0 | C3: =+General!L4 -> 0 | D3: =+General!M4 -> 0
A4: =+General!A5 -> PALMEIRAS | B4: =+General!K5 -> 0 | C4: =+General!L5 -> 0 | D4: =+General!M5 -> 0
A5: =+General!A6 -> FLAMENGO | B5: =+General!K6 -> 0 | C5: =+General!L6 -> 0 | D5: =+General!M6 -> 0
A6: =+General!A7 -> LIMA | B6: =+General!K7 -> 0 | C6: =+General!L7 -> 0 | D6: =+General!M7 -> 0
A7: =+General!A8 -> PERU | B7: =+General!K8 -> 0 | C7: =+General!L8 -> 0 | D7: =+General!M8 -> 0
A8: =+General!A9 -> VITOR ROQUE | B8: =+General!K9 -> 0 | C8: =+General!L9 -> 0 | D8: =+General!M9 -> 0
A9: =+General!A10 -> MENGAO | B9: =+General!K10 -> 0 | C9: =+General!L10 -> 0 | D9: =+General!M10 -> 0
A10: =+General!A11 -> PAULISTA | B10: =+General!K11 -> 0 | C10: =+General!L11 -> 0 | D10: =+General!M11 -> 0
A11: =+General!A12 -> CARIOCAS | B11: =+General!K12 -> 0 | C11: =+General!L12 -> 0 | D11: =+General!M12 -> 0
A12: =+General!A13 -> BRUNO ENRIQUE | B12: =+General!K13 -> 0 | C12: =+General!L13 -> 0 | D12: =+General!M13 -> 0
A13: =+General!A14 -> FLACO LOPEZ | B13: =+General!K14 -> 0 | C13: =+General!L14 -> 0 | D13: =+General!M14 -> 0
... A77: =+General!A78 -> KUOLO MUANI | B77: =+General!K78 -> 0 | C77: =+General!L78 -> 0 | D77: =+General!M78 -> 0
A79: Total
A80: Sheet

Sheet Ints x desc
A1: Agente | B1: =+General!O2 -> 45870 | C1: =+General!P2 -> 45901 | D1: =+General!Q2 -> 45931
A2: =+General!A3 -> ARGENTINA | B2: =+VLOOKUP(A2,General!$A$3:$Q$79,15,FALSE) -> 722252.39 | C2: =+VLOOKUP(A2,General!$A$3:$Q$79,16,FALSE) -> 54159 | D2: =+VLOOKUP(A2,General!$A$3:$Q$79,17,FALSE) -> 874386.78
A3: =+General!A4 -> BRASIL | B3: =+VLOOKUP(A3,General!$A$3:$Q$79,15,FALSE) -> 26092 | C3: =+VLOOKUP(A3,General!$A$3:$Q$79,16,FALSE) -> 244373.86 | D3: =+VLOOKUP(A3,General!$A$3:$Q$79,17,FALSE) -> 852521.78
A4: =+General!A5 -> PALMEIRAS | B4: =+VLOOKUP(A4,General!$A$3:$Q$79,15,FALSE) -> 1027170.5 | C4: =+VLOOKUP(A4,General!$A$3:$Q$79,16,FALSE) -> 197919.06 | D4: =+VLOOKUP(A4,General!$A$3:$Q$79,17,FALSE) -> 558901.72
A5: =+General!A6 -> FLAMENGO | B5: =+VLOOKUP(A5,General!$A$3:$Q$79,15,FALSE) -> 1373360.4 | C5: =+VLOOKUP(A5,General!$A$3:$Q$79,16,FALSE) -> 80303.26 | D5: =+VLOOKUP(A5,General!$A$3:$Q$79,17,FALSE) -> -893959.74
A6: =+General!A7 -> LIMA | B6: =+VLOOKUP(A6,General!$A$3:$Q$79,15,FALSE) -> 0 | C6: =+VLOOKUP(A6,General!$A$3:$Q$79,16,FALSE) -> 42202.7 | D6: =+VLOOKUP(A6,General!$A$3:$Q$79,17,FALSE) -> 117711.71
A7: =+General!A8 -> PERU | B7: =+VLOOKUP(A7,General!$A$3:$Q$79,15,FALSE) -> 39150.8 | C7: =+VLOOKUP(A7,General!$A$3:$Q$79,16,FALSE) -> 13582.7 | D7: =+VLOOKUP(A7,General!$A$3:$Q$79,17,FALSE) -> 28209.4
A8: =+General!A9 -> VITOR ROQUE | B8: =+VLOOKUP(A8,General!$A$3:$Q$79,15,FALSE) -> 64724.85 | C8: =+VLOOKUP(A8,General!$A$3:$Q$79,16,FALSE) -> 2088182.4 | D8: =+VLOOKUP(A8,General!$A$3:$Q$79,17,FALSE) -> -904332.21
A9: =+General!A10 -> MENGAO | B9: =+VLOOKUP(A9,General!$A$3:$Q$79,15,FALSE) -> 52353.6 | C9: =+VLOOKUP(A9,General!$A$3:$Q$79,16,FALSE) -> 122692.52 | D9: =+VLOOKUP(A9,General!$A$3:$Q$79,17,FALSE) -> 58547.5
A10: =+General!A11 -> PAULISTA | B10: =+VLOOKUP(A10,General!$A$3:$Q$79,15,FALSE) -> 0 | C10: =+VLOOKUP(A10,General!$A$3:$Q$79,16,FALSE) -> 0 | D10: =+VLOOKUP(A10,General!$A$3:$Q$79,17,FALSE) -> 0
A11: =+General!A12 -> CARIOCAS | B11: =+VLOOKUP(A11,General!$A$3:$Q$79,15,FALSE) -> 0 | C11: =+VLOOKUP(A11,General!$A$3:$Q$79,16,FALSE) -> 14349.2 | D11: =+VLOOKUP(A11,General!$A$3:$Q$79,17,FALSE) -> 0
A12: =+General!A13 -> BRUNO ENRIQUE | B12: =+VLOOKUP(A12,General!$A$3:$Q$79,15,FALSE) -> 0 | C12: =+VLOOKUP(A12,General!$A$3:$Q$79,16,FALSE) -> 79493.78 | D12: =+VLOOKUP(A12,General!$A$3:$Q$79,17,FALSE) -> 14988.1
A13: =+General!A14 -> FLACO LOPEZ | B13: =+VLOOKUP(A13,General!$A$3:$Q$79,15,FALSE) -> 0 | C13: =+VLOOKUP(A13,General!$A$3:$Q$79,16,FALSE) -> 12970.2 | D13: =+VLOOKUP(A13,General!$A$3:$Q$79,17,FALSE) -> 78687.55
... A78: =+General!A79 -> SHEVSHENKO | B78: =+VLOOKUP(A78,General!$A$3:$Q$79,15,FALSE) -> 0 | C78: =+VLOOKUP(A78,General!$A$3:$Q$79,16,FALSE) -> 0 | D78: =+VLOOKUP(A78,General!$A$3:$Q$79,17,FALSE) -> 0
A80: Total | B80: =SUM(B2:B79) -> 4618809.7 | C80: =SUM(C2:C79) -> 10462372 | D80: =SUM(D2:D79) -> 1753215.2
A81: Sheet

Sheet FCI
A1: Agente | B1: =+General!S2 -> 45870 | C1: =+General!T2 -> 45901 | D1: =+General!U2 -> 45931
A2: =+General!A3 -> ARGENTINA | B2: =+General!S3 -> 303840.26 | C2: =+General!T3 -> 419595.24 | D2: =+General!U3 -> 354205.38
A3: =+General!A4 -> BRASIL | B3: =+General!S4 -> 718839.22 | C3: =+General!T4 -> 772404.08 | D3: =+General!U4 -> 972682.96
A4: =+General!A5 -> PALMEIRAS | B4: =+General!S5 -> 1569504.6 | C4: =+General!T5 -> 1737256.1 | D4: =+General!U5 -> 1296399.3
A5: =+General!A6 -> FLAMENGO | B5: =+General!S6 -> 331360.67 | C5: =+General!T6 -> 381534.46 | D5: =+General!U6 -> 195127.25
A6: =+General!A7 -> LIMA | B6: =+General!S7 -> 13507.661 | C6: =+General!T7 -> 12319.486 | D6: =+General!U7 -> 11650.853
A7: =+General!A8 -> PERU | B7: =+General!S8 -> 61146.563 | C7: =+General!T8 -> 66127.113 | D7: =+General!U8 -> 60451.608
A8: =+General!A9 -> VITOR ROQUE | B8: =+General!S9 -> 487685.41 | C8: =+General!T9 -> 848242.12 | D8: =+General!U9 -> 1092852.1
A9: =+General!A10 -> MENGAO | B9: =+General!S10 -> 44070.02 | C9: =+General!T10 -> 45361.441 | D9: =+General!U10 -> 19290.365
A10: =+General!A11 -> PAULISTA | B10: =+General!S11 -> 5484.4902 | C10: =+General!T11 -> 0 | D10: =+General!U11 -> 96464.615
A11: =+General!A12 -> CARIOCAS | B11: =+General!S12 -> 4115.7743 | C11: =+General!T12 -> 69503.755 | D11: =+General!U12 -> 8039.2684
A12: =+General!A13 -> BRUNO ENRIQUE | B12: =+General!S13 -> 0 | C12: =+General!T13 -> 0 | D12: =+General!U13 -> 0
A13: =+General!A14 -> FLACO LOPEZ | B13: =+General!S14 -> 0 | C13: =+General!T14 -> 214.82578 | D13: =+General!U14 -> 0
... A77: =+General!A78 -> KUOLO MUANI | B77: =+General!S78 -> 0 | C77: =+General!T78 -> 0 | D77: =+General!U78 -> 0
A79: Total
A80: Sheet

Sheet Vol x cuenta
A1: =+'[2]por cuent'!A1 -> Moneda | B1: =+'[2]por cuent'!B1 -> ID cuenta | C1: =+'[2]por cuent'!C1 -> Denominacion | D1: =+'[2]por cuent'!G1 -> total | E1: =+'[2]por cuent'!H1 -> TOT EN ARS | F1: =+'[2]por cuent'!I1 -> COD
A2: =+'[2]por cuent'!A2 -> ARS | B2: =+'[2]por cuent'!B2 -> 000000101 | C2: =+'[2]por cuent'!C2 -> LERNER CAPITAL S.A. | D2: =+'[2]por cuent'!G2 -> 2.9200551e+08 | E2: =+'[2]por cuent'!H2 -> 2.9200551e+08 | F2: =+'[2]por cuent'!I2 -> 000
A3: =+'[2]por cuent'!A3 -> ARS | B3: =+'[2]por cuent'!B3 -> 114000114 | C3: =+'[2]por cuent'!C3 -> Rosario Valores S.A. - Contrapartida | D3: =+'[2]por cuent'!G3 -> 5.232594e+08 | E3: =+'[2]por cuent'!H3 -> 5.232594e+08 | F3: =+'[2]por cuent'!I3 -> 114
A4: =+'[2]por cuent'!A4 -> ARS | B4: =+'[2]por cuent'!B4 -> 114000134 | C4: =+'[2]por cuent'!C4 -> BCSA SD AXIS CAPITAL I | D4: =+'[2]por cuent'!G4 -> 1.6289108e+09 | E4: =+'[2]por cuent'!H4 -> 1.6289108e+09 | F4: =+'[2]por cuent'!I4 -> 114
A5: =+'[2]por cuent'!A5 -> ARS | B5: =+'[2]por cuent'!B5 -> 114000135 | C5: =+'[2]por cuent'!C5 -> AXIS SOCIEDAD GERENTE DE FONDOS COMUNES DE INVERSION S.A. | D5: =+'[2]por cuent'!G5 -> 4.1464033e+10 | E5: =+'[2]por cuent'!H5 -> 4.1464033e+10 | F5: =+'[2]por cuent'!I5 -> 114
A6: =+'[2]por cuent'!A6 -> ARS | B6: =+'[2]por cuent'!B6 -> 114000177 | C6: =+'[2]por cuent'!C6 -> FCI AXIS ESTRATEGIA 18 | D6: =+'[2]por cuent'!G6 -> 5.7374885e+08 | E6: =+'[2]por cuent'!H6 -> 5.7374885e+08 | F6: =+'[2]por cuent'!I6 -> 114
A7: =+'[2]por cuent'!A7 -> ARS | B7: =+'[2]por cuent'!B7 -> 114000197 | C7: =+'[2]por cuent'!C7 -> POTENCIAR SGR | D7: =+'[2]por cuent'!G7 -> 3870848.5 | E7: =+'[2]por cuent'!H7 -> 3870848.5 | F7: =+'[2]por cuent'!I7 -> 114
A8: =+'[2]por cuent'!A8 -> ARS | B8: =+'[2]por cuent'!B8 -> 114000198 | C8: =+'[2]por cuent'!C8 -> CONFEDERAR NEA SGR | D8: =+'[2]por cuent'!G8 -> 27811587 | E8: =+'[2]por cuent'!H8 -> 27811587 | F8: =+'[2]por cuent'!I8 -> 114
A9: =+'[2]por cuent'!A9 -> ARS | B9: =+'[2]por cuent'!B9 -> 114000593 | C9: =+'[2]por cuent'!C9 -> Mercado Ganadero S.A. | D9: =+'[2]por cuent'!G9 -> 8939328.8 | E9: =+'[2]por cuent'!H9 -> 8939328.8 | F9: =+'[2]por cuent'!I9 -> 114
A10: =+'[2]por cuent'!A10 -> ARS | B10: =+'[2]por cuent'!B10 -> 114114005 | C10: =+'[2]por cuent'!C10 -> ROSVAL - Operaciones Mesa Trading | D10: =+'[2]por cuent'!G10 -> 1.111167e+11 | E10: =+'[2]por cuent'!H10 -> 1.111167e+11 | F10: =+'[2]por cuent'!I10 -> 114
A11: =+'[2]por cuent'!A11 -> ARS | B11: =+'[2]por cuent'!B11 -> 114114100 | C11: =+'[2]por cuent'!C11 -> Ignacio Tillard | D11: =+'[2]por cuent'!G11 -> 9.9157901e+10 | E11: =+'[2]por cuent'!H11 -> 9.9157901e+10 | F11: =+'[2]por cuent'!I11 -> 114
A12: =+'[2]por cuent'!A12 -> ARS | B12: =+'[2]por cuent'!B12 -> 114114103 | C12: =+'[2]por cuent'!C12 -> GREENFIELD CAPITAL MARKETS S.A. | D12: =+'[2]por cuent'!G12 -> 274257242 | E12: =+'[2]por cuent'!H12 -> 274257242 | F12: =+'[2]por cuent'!I12 -> 114
... A5058: =+'[2]por cuent'!A5058 -> USDL | B5058: =+'[2]por cuent'!B5058 -> 811000027 | C5058: =+'[2]por cuent'!C5058 -> Christian Basile | D5058: =+'[2]por cuent'!G5058 -> 5450 | E5058: =+'[2]por cuent'!H5058 -> 8150911 | F5058: =+'[2]por cuent'!I5058 -> 811

Sheet Vol x merc
A1: =+[2]mercado!A1 -> Moneda | B1: =+[2]mercado!B1 -> Mercado | C1: =+[2]mercado!G1 -> total | D1: =+[2]mercado!H1 -> TOT ARS
A2: =+[2]mercado!A2 -> ARS | B2: =+[2]mercado!B2 -> [A3] A3 Mercados S.A. | C2: =+[2]mercado!G2 -> 8.3951268e+11 | D2: =+[2]mercado!H2 -> 8.3951268e+11
A3: =+[2]mercado!A3 -> ARS | B3: =+[2]mercado!B3 -> [XMEV] Bolsas y Mercados Argentinos S.A. | C3: =+[2]mercado!G3 -> 1.0383834e+13 | D3: =+[2]mercado!H3 -> 1.0383834e+13
A4: =+[2]mercado!A4 -> ARS | B4: =+[2]mercado!B4 -> [XROX] Mercado Argentino de Valores S.A. | C4: =+[2]mercado!G4 -> 1.8040929e+12 | D4: =+[2]mercado!H4 -> 1.8040929e+12
A5: =+[2]mercado!A5 -> USD | B5: =+[2]mercado!B5 -> [A3] A3 Mercados S.A. | C5: =+[2]mercado!G5 -> 28928242 | D5: =+[2]mercado!H5 -> 4.32645e+10
A6: =+[2]mercado!A6 -> USD | B6: =+[2]mercado!B6 -> [XMEV] Bolsas y Mercados Argentinos S.A. | C6: =+[2]mercado!G6 -> 7.2797532e+08 | D6: =+[2]mercado!H6 -> 1.0887453e+12
A7: =+[2]mercado!A7 -> USD | B7: =+[2]mercado!B7 -> [XROX] Mercado Argentino de Valores S.A. | C7: =+[2]mercado!G7 -> 25808677 | D7: =+[2]mercado!H7 -> 3.8598942e+10
A8: =+[2]mercado!A8 -> USDC | B8: =+[2]mercado!B8 -> [A3] A3 Mercados S.A. | C8: =+[2]mercado!G8 -> 2500000 | D8: =+[2]mercado!H8 -> 3738950000
A9: =+[2]mercado!A9 -> USDC | B9: =+[2]mercado!B9 -> [OTCM] OTC Markets Group Inc. | C9: =+[2]mercado!G9 -> 76591712 | D9: =+[2]mercado!H9 -> 1.1454903e+11
A10: =+[2]mercado!A10 -> USDC | B10: =+[2]mercado!B10 -> [XMEV] Bolsas y Mercados Argentinos S.A. | C10: =+[2]mercado!G10 -> 6.1022054e+08 | D10: =+[2]mercado!H10 -> 9.1263363e+11
A11: =+[2]mercado!A11 -> USDC | B11: =+[2]mercado!B11 -> [XNYS] NEW YORK STOCK EXCHANGE, INC. | C11: =+[2]mercado!G11 -> 1641794.4 | D11: =+[2]mercado!H11 -> 2.4554349e+09
A12: =+[2]mercado!A12 -> USDL | B12: =+[2]mercado!B12 -> [A3] A3 Mercados S.A. | C12: =+[2]mercado!G12 -> 296290 | D12: =+[2]mercado!H12 -> 4.431254e+08

Sheet Posición Valuada
A1: =+'[3]Report AUNE'!A4 -> Administrador | B1: =+'[3]Report AUNE'!B4 -> Cantidad | C1: =+'[3]Report AUNE'!C4 -> Fecha cot. | D1: =+'[3]Report AUNE'!D4 -> Precio (ARS) | E1: =+'[3]Report AUNE'!E4 -> Valuación
A2: =+'[3]Report AUNE'!A5 -> 0 | B2: =+'[3]Report AUNE'!B5 -> -1.545591e+10 | C2: =+'[3]Report AUNE'!C5 -> 45961 | D2: =+'[3]Report AUNE'!D5 -> 0 | E2: =+'[3]Report AUNE'!E5 -> -4.1817631e+11
A3: =+'[3]Report AUNE'!A7 -> [0114] ROSARIO VALORES S.A. | B3: =+'[3]Report AUNE'!B7 -> -8.6024552e+09 | C3: =+'[3]Report AUNE'!C7 -> 45961 | D3: =+'[3]Report AUNE'!D7 -> 0 | E3: =+'[3]Report AUNE'!E7 -> -3.6220954e+11
A4: =+'[3]Report AUNE'!A24 -> [0432] First Capital Markets S.A. | B4: =+'[3]Report AUNE'!B24 -> -1.9691573e+10 | C4: =+'[3]Report AUNE'!C24 -> 45961 | D4: =+'[3]Report AUNE'!D24 -> 0 | E4: =+'[3]Report AUNE'!E24 -> -2.5777774e+11
A5: =+'[3]Report AUNE'!A69 -> [0802] META Inversiones S.A. | B5: =+'[3]Report AUNE'!B69 -> 4.7683383e+08 | C5: =+'[3]Report AUNE'!C69 -> 45961 | D5: =+'[3]Report AUNE'!D69 -> 0 | E5: =+'[3]Report AUNE'!E69 -> -1.5142475e+11
A6: =+'[3]Report AUNE'!A30 -> [0479] SUPERVIELLE AGENTE DE NEGOCIACIÓN S.A.U | B6: =+'[3]Report AUNE'!B30 -> -2.0077202e+10 | C6: =+'[3]Report AUNE'!C30 -> 45961 | D6: =+'[3]Report AUNE'!D30 -> 0 | E6: =+'[3]Report AUNE'!E30 -> -1.1969468e+11
A7: =+'[3]Report AUNE'!A32 -> [0483] COPPOLA INVERSIONES S.A. | B7: =+'[3]Report AUNE'!B32 -> 9.0418324e+08 | C7: =+'[3]Report AUNE'!C32 -> 45961 | D7: =+'[3]Report AUNE'!D32 -> 0 | E7: =+'[3]Report AUNE'!E32 -> -1.17875e+11
A8: =+'[3]Report AUNE'!A33 -> [0486] UG VALORES S.A. | B8: =+'[3]Report AUNE'!B33 -> -3.7723232e+10 | C8: =+'[3]Report AUNE'!C33 -> 45961 | D8: =+'[3]Report AUNE'!D33 -> 0 | E8: =+'[3]Report AUNE'!E33 -> -7.119072e+10
A9: =+'[3]Report AUNE'!A77 -> [0834] INVERFIN S.A. | B9: =+'[3]Report AUNE'!B77 -> -4.3672389e+08 | C9: =+'[3]Report AUNE'!C77 -> 45961 | D9: =+'[3]Report AUNE'!D77 -> 0 | E9: =+'[3]Report AUNE'!E77 -> -6.6019053e+10
A10: =+'[3]Report AUNE'!A48 -> [0624] LISTRO Valores S.A. | B10: =+'[3]Report AUNE'!B48 -> -1.1221799e+09 | C10: =+'[3]Report AUNE'!C48 -> 45961 | D10: =+'[3]Report AUNE'!D48 -> 0 | E10: =+'[3]Report AUNE'!E48 -> -6.2987166e+10
A11: =+'[3]Report AUNE'!A14 -> [0401] AVANTIA VALORES S.A. | B11: =+'[3]Report AUNE'!B14 -> -4.1864578e+09 | C11: =+'[3]Report AUNE'!C14 -> 45961 | D11: =+'[3]Report AUNE'!D14 -> 0 | E11: =+'[3]Report AUNE'!E14 -> -5.0163672e+10
A12: =+'[3]Report AUNE'!A11 -> [0345] Beta Group Inversiones S.A. | B12: =+'[3]Report AUNE'!B11 -> -6.5769946e+09 | C12: =+'[3]Report AUNE'!C11 -> 45961 | D12: =+'[3]Report AUNE'!D11 -> 0 | E12: =+'[3]Report AUNE'!E11 -> -4.8147632e+10
A13: =+'[3]Report AUNE'!A36 -> [0534] Múltiplo Bursátil S.A. | B13: =+'[3]Report AUNE'!B36 -> -1.8709433e+10 | C13: =+'[3]Report AUNE'!C36 -> 45961 | D13: =+'[3]Report AUNE'!D36 -> 0 | E13: =+'[3]Report AUNE'!E36 -> -4.7092112e+10
A14: =+'[3]Report AUNE'!A75 -> [0817] VALO SECURITIES S.A.U. | B14: =+'[3]Report AUNE'!B75 -> 4.1215909e+10 | C14: =+'[3]Report AUNE'!C75 -> 45961 | D14: =+'[3]Report AUNE'!D75 -> 0 | E14: =+'[3]Report AUNE'!E75 -> -4.2556781e+10
A15: =+'[3]Report AUNE'!A74 -> [0816] CZ WEALTH MANAGEMENT S.A. | B15: =+'[3]Report AUNE'!B74 -> 2.9651408e+09 | C15: =+'[3]Report AUNE'!C74 -> 45961 | D15: =+'[3]Report AUNE'!D74 -> 0 | E15: =+'[3]Report AUNE'!E74 -> -4.1972397e+10
A16: =+'[3]Report AUNE'!A35 -> [0493] CONECTAR BURSÁTIL S.A. | B16: =+'[3]Report AUNE'!B35 -> -1.3620213e+08 | C16: =+'[3]Report AUNE'!C35 -> 45961 | D16: =+'[3]Report AUNE'!D35 -> 0 | E16: =+'[3]Report AUNE'!E35 -> -3.6494411e+10
A17: =+'[3]Report AUNE'!A57 -> [0717] Barrilli S.A. | B17: =+'[3]Report AUNE'!B57 -> -6.3229394e+09 | C17: =+'[3]Report AUNE'!C57 -> 45961 | D17: =+'[3]Report AUNE'!D57 -> 0 | E17: =+'[3]Report AUNE'!E57 -> -2.3261178e+10
A18: =+'[3]Report AUNE'!A56 -> [0687] DFC Capital Management S.A. | B18: =+'[3]Report AUNE'!B56 -> -9.8934949e+08 | C18: =+'[3]Report AUNE'!C56 -> 45961 | D18: =+'[3]Report AUNE'!D56 -> 0 | E18: =+'[3]Report AUNE'!E56 -> -2.2871067e+10
A19: =+'[3]Report AUNE'!A34 -> [0492] REGIONAL INVESTMENT CONSULTING S.A. | B19: =+'[3]Report AUNE'!B34 -> -8.7437971e+09 | C19: =+'[3]Report AUNE'!C34 -> 45961 | D19: =+'[3]Report AUNE'!D34 -> 0 | E19: =+'[3]Report AUNE'!E34 -> -2.0793071e+10
A20: =+'[3]Report AUNE'!A61 -> [0758] GOROSTIAGA BURSATIL S.A. | B20: =+'[3]Report AUNE'!B61 -> -2.4515065e+09 | C20: =+'[3]Report AUNE'!C61 -> 45961 | D20: =+'[3]Report AUNE'!D61 -> 0 | E20: =+'[3]Report AUNE'!E61 -> -1.6532389e+10
A21: =+'[3]Report AUNE'!A38 -> [0560] Omega Bursátil S.A. | B21: =+'[3]Report AUNE'!B38 -> -6.4113482e+08 | C21: =+'[3]Report AUNE'!C38 -> 45961 | D21: =+'[3]Report AUNE'!D38 -> 0 | E21: =+'[3]Report AUNE'!E38 -> -1.5028886e+10
A22: =+'[3]Report AUNE'!A22 -> [0423] REAL MARKET S.A. | B22: =+'[3]Report AUNE'!B22 -> -3.2410956e+09 | C22: =+'[3]Report AUNE'!C22 -> 45961 | D22: =+'[3]Report AUNE'!D22 -> 0 | E22: =+'[3]Report AUNE'!E22 -> -1.3669192e+10
A23: =+'[3]Report AUNE'!A43 -> [0602] Fernando Bibe e Hijos S.A. | B23: =+'[3]Report AUNE'!B43 -> -1.0768768e+08 | C23: =+'[3]Report AUNE'!C43 -> 45961 | D23: =+'[3]Report AUNE'!D43 -> 0 | E23: =+'[3]Report AUNE'!E43 -> -1.2103106e+10
A24: =+'[3]Report AUNE'!A64 -> [0766] AWA GLOBAL S.A. | B24: =+'[3]Report AUNE'!B64 -> -1.9820317e+09 | C24: =+'[3]Report AUNE'!C64 -> 45961 | D24: =+'[3]Report AUNE'!D64 -> 0 | E24: =+'[3]Report AUNE'!E64 -> -1.10451e+10
A25: =+'[3]Report AUNE'!A25 -> [0435] Inverstart SA | B25: =+'[3]Report AUNE'!B25 -> -4.9684303e+08 | C25: =+'[3]Report AUNE'!C25 -> 45961 | D25: =+'[3]Report AUNE'!D25 -> 0 | E25: =+'[3]Report AUNE'!E25 -> -9.743983e+09
A26: =+'[3]Report AUNE'!A63 -> [0765] Hoss S.A | B26: =+'[3]Report AUNE'!B63 -> -1.623426e+08 | C26: =+'[3]Report AUNE'!C63 -> 45961 | D26: =+'[3]Report AUNE'!D63 -> 0 | E26: =+'[3]Report AUNE'!E63 -> -8.7971519e+09
A27: =+'[3]Report AUNE'!A28 -> [0465] Industria Compañía Bursátil S.A. | B27: =+'[3]Report AUNE'!B28 -> -3.097123e+09 | C27: =+'[3]Report AUNE'!C28 -> 45961 | D27: =+'[3]Report AUNE'!D28 -> 0 | E27: =+'[3]Report AUNE'!E28 -> -8.5049507e+09
A28: =+'[3]Report AUNE'!A10 -> [0344] Bafomet SA | B28: =+'[3]Report AUNE'!B10 -> -8.8576271e+08 | C28: =+'[3]Report AUNE'!C10 -> 45961 | D28: =+'[3]Report AUNE'!D10 -> 0 | E28: =+'[3]Report AUNE'!E10 -> -7.9943068e+09
A29: =+'[3]Report AUNE'!A73 -> [0812] San Cristóbal Servicios Financieros S.A. | B29: =+'[3]Report AUNE'!B73 -> 3.7342333e+09 | C29: =+'[3]Report AUNE'!C73 -> 45961 | D29: =+'[3]Report AUNE'!D73 -> 0 | E29: =+'[3]Report AUNE'!E73 -> -7.937348e+09
A30: =+'[3]Report AUNE'!A40 -> [0568] AXON CAPITAL S.A. | B30: =+'[3]Report AUNE'!B40 -> -3.7827164e+09 | C30: =+'[3]Report AUNE'!C40 -> 45961 | D30: =+'[3]Report AUNE'!D40 -> 0 | E30: =+'[3]Report AUNE'!E40 -> -5.7401838e+09
A31: =+'[3]Report AUNE'!A71 -> [0806] INVERSIONES CUYANAS S.A. | B31: =+'[3]Report AUNE'!B71 -> -1.5296656e+09 | C31: =+'[3]Report AUNE'!C71 -> 45961 | D31: =+'[3]Report AUNE'!D71 -> 0 | E31: =+'[3]Report AUNE'!E71 -> -5.6031434e+09
A32: =+'[3]Report AUNE'!A39 -> [0565] BUENOS AIRES CREDITOS Y VALORES SOCIEDAD ANONIMA | B32: =+'[3]Report AUNE'!B39 -> 1.7119916e+09 | C32: =+'[3]Report AUNE'!C39 -> 45961 | D32: =+'[3]Report AUNE'!D39 -> 0 | E32: =+'[3]Report AUNE'!E39 -> -5.4387365e+09
A33: =+'[3]Report AUNE'!A16 -> [0405] PUERTOS SRL | B33: =+'[3]Report AUNE'!B16 -> -1.6786041e+09 | C33: =+'[3]Report AUNE'!C16 -> 45961 | D33: =+'[3]Report AUNE'!D16 -> 0 | E33: =+'[3]Report AUNE'!E16 -> -4.1489095e+09
A34: =+'[3]Report AUNE'!A23 -> [0424] Vector Investments S.A. | B34: =+'[3]Report AUNE'!B23 -> -2.2132004e+08 | C34: =+'[3]Report AUNE'!C23 -> 45961 | D34: =+'[3]Report AUNE'!D23 -> 0 | E34: =+'[3]Report AUNE'!E23 -> -3.9121751e+09
A35: =+'[3]Report AUNE'!A37 -> [0554] Zona Bursátil S.A. | B35: =+'[3]Report AUNE'!B37 -> -2.8841904e+09 | C35: =+'[3]Report AUNE'!C37 -> 45961 | D35: =+'[3]Report AUNE'!D37 -> 0 | E35: =+'[3]Report AUNE'!E37 -> -3.8367427e+09
A36: =+'[3]Report AUNE'!A20 -> [0417] Palm Inversiones S.A. | B36: =+'[3]Report AUNE'!B20 -> -19820990 | C36: =+'[3]Report AUNE'!C20 -> 45961 | D36: =+'[3]Report AUNE'!D20 -> 0 | E36: =+'[3]Report AUNE'!E20 -> -3.293924e+09
A37: =+'[3]Report AUNE'!A79 -> [0865] GLOBAL MARKET S.A. | B37: =+'[3]Report AUNE'!B79 -> 6.8928443e+08 | C37: =+'[3]Report AUNE'!C79 -> 45961 | D37: =+'[3]Report AUNE'!D79 -> 0 | E37: =+'[3]Report AUNE'!E79 -> -2.9271045e+09
A38: =+'[3]Report AUNE'!A26 -> [0447] BAMBA VALORES SA | B38: =+'[3]Report AUNE'!B26 -> -1.2970497e+09 | C38: =+'[3]Report AUNE'!C26 -> 45961 | D38: =+'[3]Report AUNE'!D26 -> 0 | E38: =+'[3]Report AUNE'!E26 -> -2.7748604e+09
A39: =+'[3]Report AUNE'!A80 -> [0868] WETPAMPEAN HDRR S.A. | B39: =+'[3]Report AUNE'!B80 -> -7.5184936e+08 | C39: =+'[3]Report AUNE'!C80 -> 45961 | D39: =+'[3]Report AUNE'!D80 -> 0 | E39: =+'[3]Report AUNE'!E80 -> -2.6628966e+09
A40: =+'[3]Report AUNE'!A72 -> [0811] VERLIN CAPITAL S.A. | B40: =+'[3]Report AUNE'!B72 -> -4.9098948e+08 | C40: =+'[3]Report AUNE'!C72 -> 45961 | D40: =+'[3]Report AUNE'!D72 -> 0 | E40: =+'[3]Report AUNE'!E72 -> -2.4952697e+09
...
